<?xml version="1.0" ?>
<robot name="Right arm">
  <link name="Link 00">
    <inertial>
	  <origin rpy="0 0 0" xyz="0 0 0"/>
      <mass value="1"/>
      <inertia ixx="1" iyy="1" izz="1" ixy="0" ixz="0" iyz="0"/>
    </inertial>
    <visual>
      <origin rpy="0 0 0" xyz="0 0 0"/>
      <geometry>
        <mesh filename="Link00.stl"/>
      </geometry>
    </visual>
  </link>
  <link name="Link 02">
    <inertial>
	  <origin rpy="0 0 0" xyz="0 0 0"/>
      <mass value="1"/>
      <inertia ixx="1" iyy="1" izz="1" ixy="0" ixz="0" iyz="0"/>
    </inertial>
    <visual>
      <origin rpy="0 0 0" xyz="0 0 0"/>
      <geometry>
        <mesh filename="Link02.stl"/>
      </geometry>
    </visual>
  </link>
  <joint name="Joint 00-02" type="prismatic">
    <origin rpy="1.5708 0 1.5708" xyz="0 0 0.4"/>
    <axis xyz="1 0 0"/>
    <parent link="Link 00"/>
    <child link="Link 02"/>
    <dynamics damping="0.1"/>
    <limit lower="-0.5" upper="0.5" effort="100" velocity="1"/>
  </joint>
  <link name="Link 03">
    <inertial>
	  <origin rpy="0 0 0" xyz="0 0 0"/>
      <mass value="1"/>
      <inertia ixx="1" iyy="1" izz="1" ixy="0" ixz="0" iyz="0"/>
    </inertial>
    <visual>
      <origin rpy="0 0 0" xyz="0 0 0"/>
      <geometry>
        <mesh filename="Link03.stl"/>
      </geometry>
    </visual>
  </link>
  <joint name="Joint 02-03" type="revolute">
    <origin rpy="0 0 0.2327" xyz="0 0 -0.116"/>
    <axis xyz="0 0 1"/>
    <parent link="Link 02"/>
    <child link="Link 03"/>
    <dynamics damping="0.1"/>
    <limit lower="-0.3142" upper="0.7400" effort="100" velocity="1"/>
  </joint>
  <link name="Link 04">
    <inertial>
	  <origin rpy="0 0 0" xyz="0 0 0"/>
      <mass value="1"/>
      <inertia ixx="1" iyy="1" izz="1" ixy="0" ixz="0" iyz="0"/>
    </inertial>
    <visual>
      <origin rpy="0 0 0" xyz="0 0 0"/>
      <geometry>
        <mesh filename="Link04.stl"/>
      </geometry>
    </visual>
  </link>
  <joint name="Joint 03-04" type="revolute">
    <origin rpy="1.5708 0 -0.2327" xyz="0.155 0 0"/>
    <axis xyz="0 1 0"/>
    <parent link="Link 03"/>
    <child link="Link 04"/>
    <dynamics damping="0.1"/>
    <limit lower="-0.7400" upper="0.3142" effort="100" velocity="1"/>
  </joint>
  <link name="Link 05">
    <inertial>
	  <origin rpy="0 0 0" xyz="0 0 0"/>
      <mass value="1"/>
      <inertia ixx="1" iyy="1" izz="1" ixy="0" ixz="0" iyz="0"/>
    </inertial>
    <visual>
      <origin rpy="0 0 0" xyz="0 0 0"/>
      <geometry>
        <mesh filename="Link05.stl"/>
      </geometry>
    </visual>
  </link>
  <joint name="Joint 04-05" type="revolute">
    <origin rpy="0 0 -0.2618" xyz="0.075 0 -0.024"/>
    <axis xyz="0 0 1"/>
    <parent link="Link 04"/>
    <child link="Link 05"/>
    <dynamics damping="0.1"/>
    <limit lower="-1.8326" upper="1.0123" effort="100" velocity="1"/>
  </joint>
  <link name="Link 06">
    <inertial>
	  <origin rpy="0 0 0" xyz="0 0 0"/>
      <mass value="1"/>
      <inertia ixx="1" iyy="1" izz="1" ixy="0" ixz="0" iyz="0"/>
    </inertial>
    <visual>
      <origin rpy="0 0 0" xyz="0 0 0"/>
      <geometry>
        <mesh filename="Link06.stl"/>
      </geometry>
    </visual>
  </link>
  <joint name="Joint 05-06" type="revolute">
    <origin rpy="0 0 1.1345" xyz="0.180 0 0.024"/>
    <axis xyz="0 0 1"/>
    <parent link="Link 05"/>
    <child link="Link 06"/>
    <dynamics damping="0.1"/>
    <limit lower="-1.8151" upper="2.7576" effort="100" velocity="1"/>
  </joint>
  <link name="Link 07">
    <inertial>
	  <origin rpy="0 0 0" xyz="0 0 0"/>
      <mass value="1"/>
      <inertia ixx="1" iyy="1" izz="1" ixy="0" ixz="0" iyz="0"/>
    </inertial>
    <visual>
      <origin rpy="0 0 0" xyz="0 0 0"/>
      <geometry>
        <mesh filename="Link07.stl"/>
      </geometry>
    </visual>
  </link>
  <joint name="Joint 06-07" type="revolute">
    <origin rpy="1.5708 0 0.4887" xyz="0.1 0 0.086"/>
    <axis xyz="0 1 0"/>
    <parent link="Link 06"/>
    <child link="Link 07"/>
    <dynamics damping="0.1"/>
    <limit lower="-3.0107" upper="2.9671" effort="100" velocity="1"/>
  </joint>
  <link name="Link 08">
    <inertial>
	  <origin rpy="0 0 0" xyz="0 0 0"/>
      <mass value="1"/>
      <inertia ixx="1" iyy="1" izz="1" ixy="0" ixz="0" iyz="0"/>
    </inertial>
    <visual>
      <origin rpy="0 0 0" xyz="0 0 0"/>
      <geometry>
        <mesh filename="Link08.stl"/>
      </geometry>
    </visual>
  </link>
  <joint name="Joint 07-08" type="revolute">
    <origin rpy="1.5708 0 1.5708" xyz="0 0 0"/>
    <axis xyz="0 1 0"/>
    <parent link="Link 07"/>
    <child link="Link 08"/>
    <dynamics damping="0.1"/>
    <limit lower="1.5708" upper="3.5779" effort="100" velocity="1"/>
  </joint>
  <link name="Link 09">
    <inertial>
	  <origin rpy="0 0 0" xyz="0 0 0"/>
      <mass value="1"/>
      <inertia ixx="1" iyy="1" izz="1" ixy="0" ixz="0" iyz="0"/>
    </inertial>
    <visual>
      <origin rpy="0 0 0" xyz="0 0 0"/>
      <geometry>
        <mesh filename="Link09.stl"/>
      </geometry>
    </visual>
  </link>
  <joint name="Joint 08-09" type="revolute">
    <origin rpy="-1.5708 0 0" xyz="0 0 0.1505"/>
    <axis xyz="0 1 0"/>
    <parent link="Link 08"/>
    <child link="Link 09"/>
    <dynamics damping="0.1"/>
    <limit lower="-1.5708" upper="1.5882" effort="100" velocity="1"/>
  </joint>
  <link name="Link 10">
    <inertial>
	  <origin rpy="0 0 0" xyz="0 0 0"/>
      <mass value="1"/>
      <inertia ixx="1" iyy="1" izz="1" ixy="0" ixz="0" iyz="0"/>
    </inertial>
    <visual>
      <origin rpy="0 0 0" xyz="0 0 0"/>
      <geometry>
        <mesh filename="Link10.stl"/>
      </geometry>
    </visual>
  </link>
  <joint name="Joint 09-10" type="revolute">
    <origin rpy="-1.5708 0 -1.5708" xyz="0.035 0 0"/>
    <axis xyz="0 1 0"/>
    <parent link="Link 09"/>
    <child link="Link 10"/>
    <dynamics damping="0.1"/>
    <limit lower="-2.4260" upper="-0.6981" effort="100" velocity="1"/>
  </joint>
  <link name="Link 11">
    <inertial>
	  <origin rpy="0 0 0" xyz="0 0 0"/>
      <mass value="1"/>
      <inertia ixx="1" iyy="1" izz="1" ixy="0" ixz="0" iyz="0"/>
    </inertial>
    <visual>
      <origin rpy="0 0 0" xyz="0 0 0"/>
      <geometry>
        <mesh filename="Link11.stl"/>
      </geometry>
    </visual>
  </link>
  <joint name="Joint 10-11" type="revolute">
    <origin rpy="1.5708 0 0.2967" xyz="0.0551 0 0.05865"/>
    <axis xyz="0 1 0"/>
    <parent link="Link 10"/>
    <child link="Link 11"/>
    <dynamics damping="0.1"/>
    <limit lower="-3.1416" upper="3.1416" effort="100" velocity="1"/>
  </joint>
</robot>